2024-09-24 15:03:57 - [32m Атака на lupatik произведена успешно[39m
2024-09-24 15:03:57 - DA
2024-09-24 15:03:58 - DA
2024-09-24 15:03:59 - DA
2024-09-24 15:09:41 - Проверочка
2024-09-24 15:25:59 - Проверочка
2024-09-24 15:25:59 - Starting new HTTPS connection (1): www.google.com:443
2024-09-24 15:25:59 - https://www.google.com:443 "GET / HTTP/1.1" 200 None
2024-09-24 15:25:59 - Необработанное исключение
Traceback (most recent call last):
  File "C:\Python\BattleKnigt\tets.py", line 14, in <module>
    gg()
  File "C:\Python\BattleKnigt\tets.py", line 10, in gg
    p_log(Fore.LIGHTBLACK_EX + " response ответ" + Fore.RESET, response.status_code)
  File "C:\Python\BattleKnigt\logs\logs.py", line 7, in p_log
    message = " ".join(args)
              ^^^^^^^^^^^^^^
TypeError: sequence item 1: expected str instance, int found
2024-09-24 15:27:55 - Необработанное исключение
Traceback (most recent call last):
  File "C:\Python\BattleKnigt\tets.py", line 14, in <module>
    gg()
  File "C:\Python\BattleKnigt\tets.py", line 8, in gg
    p_log("Проверочка")
  File "C:\Python\BattleKnigt\logs\logs.py", line 7, in p_log
    message = str(args[0]) + str(args[1])
                                 ~~~~^^^
IndexError: tuple index out of range
2024-09-24 15:28:12 - Starting new HTTPS connection (1): www.google.com:443
2024-09-24 15:28:13 - https://www.google.com:443 "GET / HTTP/1.1" 200 None
2024-09-24 15:31:13 - Проверочка
2024-09-24 15:31:13 - Starting new HTTPS connection (1): www.google.com:443
2024-09-24 15:31:13 - https://www.google.com:443 "GET / HTTP/1.1" 200 None
2024-09-24 15:31:13 - [90m response ответ[39m 200
2024-09-24 15:32:32 - Проверочка
2024-09-24 15:32:32 - Starting new HTTPS connection (1): www.go21sdfsogle.com:443
2024-09-24 15:32:32 - Необработанное исключение
Traceback (most recent call last):
  File "C:\Python\BattleKnigt\venv\Lib\site-packages\urllib3\connection.py", line 198, in _new_conn
    sock = connection.create_connection(
           ^^^^^^^^^^^^^^^^^^^^^^^^^^^^^
  File "C:\Python\BattleKnigt\venv\Lib\site-packages\urllib3\util\connection.py", line 60, in create_connection
    for res in socket.getaddrinfo(host, port, family, socket.SOCK_STREAM):
               ^^^^^^^^^^^^^^^^^^^^^^^^^^^^^^^^^^^^^^^^^^^^^^^^^^^^^^^^^^
  File "C:\Python311\Lib\socket.py", line 962, in getaddrinfo
    for res in _socket.getaddrinfo(host, port, family, type, proto, flags):
               ^^^^^^^^^^^^^^^^^^^^^^^^^^^^^^^^^^^^^^^^^^^^^^^^^^^^^^^^^^^
socket.gaierror: [Errno 11001] getaddrinfo failed

The above exception was the direct cause of the following exception:

Traceback (most recent call last):
  File "C:\Python\BattleKnigt\venv\Lib\site-packages\urllib3\connectionpool.py", line 793, in urlopen
    response = self._make_request(
               ^^^^^^^^^^^^^^^^^^^
  File "C:\Python\BattleKnigt\venv\Lib\site-packages\urllib3\connectionpool.py", line 491, in _make_request
    raise new_e
  File "C:\Python\BattleKnigt\venv\Lib\site-packages\urllib3\connectionpool.py", line 467, in _make_request
    self._validate_conn(conn)
  File "C:\Python\BattleKnigt\venv\Lib\site-packages\urllib3\connectionpool.py", line 1099, in _validate_conn
    conn.connect()
  File "C:\Python\BattleKnigt\venv\Lib\site-packages\urllib3\connection.py", line 616, in connect
    self.sock = sock = self._new_conn()
                       ^^^^^^^^^^^^^^^^
  File "C:\Python\BattleKnigt\venv\Lib\site-packages\urllib3\connection.py", line 205, in _new_conn
    raise NameResolutionError(self.host, self, e) from e
urllib3.exceptions.NameResolutionError: <urllib3.connection.HTTPSConnection object at 0x0000010DE9EE89D0>: Failed to resolve 'www.go21sdfsogle.com' ([Errno 11001] getaddrinfo failed)

The above exception was the direct cause of the following exception:

Traceback (most recent call last):
  File "C:\Python\BattleKnigt\venv\Lib\site-packages\requests\adapters.py", line 486, in send
    resp = conn.urlopen(
           ^^^^^^^^^^^^^
  File "C:\Python\BattleKnigt\venv\Lib\site-packages\urllib3\connectionpool.py", line 847, in urlopen
    retries = retries.increment(
              ^^^^^^^^^^^^^^^^^^
  File "C:\Python\BattleKnigt\venv\Lib\site-packages\urllib3\util\retry.py", line 515, in increment
    raise MaxRetryError(_pool, url, reason) from reason  # type: ignore[arg-type]
    ^^^^^^^^^^^^^^^^^^^^^^^^^^^^^^^^^^^^^^^^^^^^^^^^^^^
urllib3.exceptions.MaxRetryError: HTTPSConnectionPool(host='www.go21sdfsogle.com', port=443): Max retries exceeded with url: / (Caused by NameResolutionError("<urllib3.connection.HTTPSConnection object at 0x0000010DE9EE89D0>: Failed to resolve 'www.go21sdfsogle.com' ([Errno 11001] getaddrinfo failed)"))

During handling of the above exception, another exception occurred:

Traceback (most recent call last):
  File "C:\Python\BattleKnigt\tets.py", line 14, in <module>
    gg()
  File "C:\Python\BattleKnigt\tets.py", line 9, in gg
    response = requests.get("https://www.go21sdfsogle.com/")
               ^^^^^^^^^^^^^^^^^^^^^^^^^^^^^^^^^^^^^^^^^^^^^
  File "C:\Python\BattleKnigt\venv\Lib\site-packages\requests\api.py", line 73, in get
    return request("get", url, params=params, **kwargs)
           ^^^^^^^^^^^^^^^^^^^^^^^^^^^^^^^^^^^^^^^^^^^^
  File "C:\Python\BattleKnigt\venv\Lib\site-packages\requests\api.py", line 59, in request
    return session.request(method=method, url=url, **kwargs)
           ^^^^^^^^^^^^^^^^^^^^^^^^^^^^^^^^^^^^^^^^^^^^^^^^^
  File "C:\Python\BattleKnigt\venv\Lib\site-packages\requests\sessions.py", line 589, in request
    resp = self.send(prep, **send_kwargs)
           ^^^^^^^^^^^^^^^^^^^^^^^^^^^^^^
  File "C:\Python\BattleKnigt\venv\Lib\site-packages\requests\sessions.py", line 703, in send
    r = adapter.send(request, **kwargs)
        ^^^^^^^^^^^^^^^^^^^^^^^^^^^^^^^
  File "C:\Python\BattleKnigt\venv\Lib\site-packages\requests\adapters.py", line 519, in send
    raise ConnectionError(e, request=request)
requests.exceptions.ConnectionError: HTTPSConnectionPool(host='www.go21sdfsogle.com', port=443): Max retries exceeded with url: / (Caused by NameResolutionError("<urllib3.connection.HTTPSConnection object at 0x0000010DE9EE89D0>: Failed to resolve 'www.go21sdfsogle.com' ([Errno 11001] getaddrinfo failed)"))
2024-09-24 15:36:52 - Проверочка
2024-09-24 15:36:52 - [90m response ответ[39m 200
2024-09-24 15:44:28 - Проверочка
2024-09-24 15:44:29 - [90m response ответ[39m 200
2024-09-24 15:45:16 - Проверочка
2024-09-24 15:45:16 - [90m response ответ[39m 200
2024-09-24 15:46:49 - Проверочка
2024-09-24 15:46:49 - [90m response ответ[39m 200
2024-09-24 15:49:15 - Проверочка
2024-09-24 15:49:15 - Необработанное исключение
Traceback (most recent call last):
  File "C:\Python\BattleKnigt\venv\Lib\site-packages\urllib3\connection.py", line 198, in _new_conn
    sock = connection.create_connection(
           ^^^^^^^^^^^^^^^^^^^^^^^^^^^^^
  File "C:\Python\BattleKnigt\venv\Lib\site-packages\urllib3\util\connection.py", line 60, in create_connection
    for res in socket.getaddrinfo(host, port, family, socket.SOCK_STREAM):
               ^^^^^^^^^^^^^^^^^^^^^^^^^^^^^^^^^^^^^^^^^^^^^^^^^^^^^^^^^^
  File "C:\Python311\Lib\socket.py", line 962, in getaddrinfo
    for res in _socket.getaddrinfo(host, port, family, type, proto, flags):
               ^^^^^^^^^^^^^^^^^^^^^^^^^^^^^^^^^^^^^^^^^^^^^^^^^^^^^^^^^^^
socket.gaierror: [Errno 11001] getaddrinfo failed

The above exception was the direct cause of the following exception:

Traceback (most recent call last):
  File "C:\Python\BattleKnigt\venv\Lib\site-packages\urllib3\connectionpool.py", line 793, in urlopen
    response = self._make_request(
               ^^^^^^^^^^^^^^^^^^^
  File "C:\Python\BattleKnigt\venv\Lib\site-packages\urllib3\connectionpool.py", line 491, in _make_request
    raise new_e
  File "C:\Python\BattleKnigt\venv\Lib\site-packages\urllib3\connectionpool.py", line 467, in _make_request
    self._validate_conn(conn)
  File "C:\Python\BattleKnigt\venv\Lib\site-packages\urllib3\connectionpool.py", line 1099, in _validate_conn
    conn.connect()
  File "C:\Python\BattleKnigt\venv\Lib\site-packages\urllib3\connection.py", line 616, in connect
    self.sock = sock = self._new_conn()
                       ^^^^^^^^^^^^^^^^
  File "C:\Python\BattleKnigt\venv\Lib\site-packages\urllib3\connection.py", line 205, in _new_conn
    raise NameResolutionError(self.host, self, e) from e
urllib3.exceptions.NameResolutionError: <urllib3.connection.HTTPSConnection object at 0x000001F15B7C88D0>: Failed to resolve 'www.goo11gle.com' ([Errno 11001] getaddrinfo failed)

The above exception was the direct cause of the following exception:

Traceback (most recent call last):
  File "C:\Python\BattleKnigt\venv\Lib\site-packages\requests\adapters.py", line 486, in send
    resp = conn.urlopen(
           ^^^^^^^^^^^^^
  File "C:\Python\BattleKnigt\venv\Lib\site-packages\urllib3\connectionpool.py", line 847, in urlopen
    retries = retries.increment(
              ^^^^^^^^^^^^^^^^^^
  File "C:\Python\BattleKnigt\venv\Lib\site-packages\urllib3\util\retry.py", line 515, in increment
    raise MaxRetryError(_pool, url, reason) from reason  # type: ignore[arg-type]
    ^^^^^^^^^^^^^^^^^^^^^^^^^^^^^^^^^^^^^^^^^^^^^^^^^^^
urllib3.exceptions.MaxRetryError: HTTPSConnectionPool(host='www.goo11gle.com', port=443): Max retries exceeded with url: / (Caused by NameResolutionError("<urllib3.connection.HTTPSConnection object at 0x000001F15B7C88D0>: Failed to resolve 'www.goo11gle.com' ([Errno 11001] getaddrinfo failed)"))

During handling of the above exception, another exception occurred:

Traceback (most recent call last):
  File "C:\Python\BattleKnigt\tets.py", line 14, in <module>
    gg()
  File "C:\Python\BattleKnigt\tets.py", line 9, in gg
    response = requests.get("https://www.goo11gle.com/")
               ^^^^^^^^^^^^^^^^^^^^^^^^^^^^^^^^^^^^^^^^^
  File "C:\Python\BattleKnigt\venv\Lib\site-packages\requests\api.py", line 73, in get
    return request("get", url, params=params, **kwargs)
           ^^^^^^^^^^^^^^^^^^^^^^^^^^^^^^^^^^^^^^^^^^^^
  File "C:\Python\BattleKnigt\venv\Lib\site-packages\requests\api.py", line 59, in request
    return session.request(method=method, url=url, **kwargs)
           ^^^^^^^^^^^^^^^^^^^^^^^^^^^^^^^^^^^^^^^^^^^^^^^^^
  File "C:\Python\BattleKnigt\venv\Lib\site-packages\requests\sessions.py", line 589, in request
    resp = self.send(prep, **send_kwargs)
           ^^^^^^^^^^^^^^^^^^^^^^^^^^^^^^
  File "C:\Python\BattleKnigt\venv\Lib\site-packages\requests\sessions.py", line 703, in send
    r = adapter.send(request, **kwargs)
        ^^^^^^^^^^^^^^^^^^^^^^^^^^^^^^^
  File "C:\Python\BattleKnigt\venv\Lib\site-packages\requests\adapters.py", line 519, in send
    raise ConnectionError(e, request=request)
requests.exceptions.ConnectionError: HTTPSConnectionPool(host='www.goo11gle.com', port=443): Max retries exceeded with url: / (Caused by NameResolutionError("<urllib3.connection.HTTPSConnection object at 0x000001F15B7C88D0>: Failed to resolve 'www.goo11gle.com' ([Errno 11001] getaddrinfo failed)"))
2024-09-24 15:49:36 - Проверочка
2024-09-24 15:49:36 - [90m response ответ[39m 200
